Workbook

Sheet Sheet1
A1: เลขรับเรื่อง | B1: เลขประมาณการ | C1: WBS No. | D1: เลขรับเรื่อง | E1: บัญชี | F1: ขื่อบัญชี | G1: Status | H1: User Status | I1: ค่าจริง | J1: ค่าประมาณการ | K1: ผลต่าง | L1: หน่วยงานสนาม | M1: TECO Date
A2: 320000069587 | B2: 6960 | C2: S/60.69.00010.02 | D2: 320000069587 | E2: 4120500010 | F2: รายได้-รับเหมาสายใน | G2: TECO | H2: ACCO | I2: -2361.82 | J2: -2361.82 | K2: 0 | M2: 44301
A3: 320000099933 | B3: 6961 | C3: S/61.69.00070.05 | D3: 320000099933 | E3: 4120500010 | F3: รายได้-รับเหมาสายใน | G3: CRTD | H3: WACT | I3: 0 | J3: -107850.47 | K3: 107850.47
A4: 320000099932 | B4: 6961 | C4: S/61.69.00074.05 | D4: 320000099932 | E4: 4120500010 | F4: รายได้-รับเหมาสายใน | G4: CRTD | H4: WACT | I4: 0 | J4: -132605.87 | K4: 132605.87
A5: 300001473823 | B5: 6961 | C5: S/61.69.00119.02 | D5: 300001473823 | E5: 4120500010 | F5: รายได้-รับเหมาสายใน | G5: CRTD | H5: WACT | I5: 0 | J5: -2233.64 | K5: 2233.64
A6: 300001459003 | B6: 6961 | C6: S/61.69.00140.02 | D6: 300001459003 | E6: 4120500010 | F6: รายได้-รับเหมาสายใน | G6: CRTD | H6: WACT | I6: 0 | J6: -2392.52 | K6: 2392.52
A7: 320000099932 | B7: 6961 | C7: S/61.69.00075.05 | D7: 320000099932 | E7: 4120500010 | F7: รายได้-รับเหมาสายใน | G7: CRTD | H7: WACT | I7: 0 | J7: -169431.51 | K7: 169431.51
A8: 300001495824 | B8: 6961 | C8: S/61.69.00135.02 | D8: 300001495824 | E8: 4120500010 | F8: รายได้-รับเหมาสายใน | G8: CRTD | H8: WACT | I8: 0 | J8: -2299.07 | K8: 2299.07
A9: 300001495822 | B9: 6961 | C9: S/61.69.00139.02 | D9: 300001495822 | E9: 4120500010 | F9: รายได้-รับเหมาสายใน | G9: CRTD | H9: WACT | I9: 0 | J9: -1168.22 | K9: 1168.22
A10: 300001495823 | B10: 6961 | C10: S/61.69.00136.02 | D10: 300001495823 | E10: 4120500010 | F10: รายได้-รับเหมาสายใน | G10: CRTD | H10: WACT | I10: 0 | J10: -5355.14 | K10: 5355.14
A11: 320000108916 | B11: 6962 | C11: S/62.69.00012.05 | D11: 320000108916 | E11: 4120500010 | F11: รายได้-รับเหมาสายใน | G11: CRTD | H11: WACT | I11: 0 | J11: -120280.14 | K11: 120280.14
A12: 320000107734 | B12: 6962 | C12: S/62.69.00010.02 | D12: 320000107734 | E12: 4120500010 | F12: รายได้-รับเหมาสายใน | G12: TECO | H12: ACCO | I12: -226297.55 | J12: -226297.55 | K12: 0 | M12: 44551
A13: 320000108916 | B13: 6962 | C13: S/62.69.00015.05 | D13: 320000108916 | E13: 4120500010 | F13: รายได้-รับเหมาสายใน | G13: CRTD | H13: WACT | I13: 0 | J13: -12140.42 | K13: 12140.42
A14: 320000107734 | B14: 6962 | C14: S/62.69.00011.02 | D14: 320000107734 | E14: 4120500010 | F14: รายได้-รับเหมาสายใน | G14: TECO | H14: ACCO | I14: -146898.71 | J14: -146898.71 | K14: 0 | M14: 44551
A15: 300001704577 | B15: 6962 | C15: S/62.69.00208.02 | D15: 300001704577 | E15: 4120500010 | F15: รายได้-รับเหมาสายใน | G15: CRTD | H15: WACT | I15: 0 | J15: -3603.81 | K15: 3603.81
A16: 300001704578 | B16: 6962 | C16: S/62.69.00216.02 | D16: 300001704578 | E16: 4120500010 | F16: รายได้-รับเหมาสายใน | G16: CRTD | H16: WACT | I16: 0 | J16: -3603.81 | K16: 3603.81
A17: 300001045005 | B17: 6962 | C17: S/62.69.00128.02 | D17: 300001045005 | E17: 4120500010 | F17: รายได้-รับเหมาสายใน | G17: CRTD | H17: WACT | I17: 0 | J17: -2196.26 | K17: 2196.26
A18: 300001047950 | B18: 6962 | C18: S/62.69.00119.02 | D18: 300001047950 | E18: 4120500010 | F18: รายได้-รับเหมาสายใน | G18: CRTD | H18: WACT | I18: 0 | J18: -1158.88 | K18: 1158.88
A19: 300001047860 | B19: 6962 | C19: S/62.69.00123.02 | D19: 300001047860 | E19: 4120500010 | F19: รายได้-รับเหมาสายใน | G19: CRTD | H19: WACT | I19: 0 | J19: -2719.63 | K19: 2719.63
A20: 300001473200 | B20: 6962 | C20: S/62.69.00120.02 | D20: 300001473200 | E20: 4120500010 | F20: รายได้-รับเหมาสายใน | G20: CRTD | H20: WACT | I20: 0 | J20: -1168.22 | K20: 1168.22
A21: 300001047794 | B21: 6962 | C21: S/62.69.00132.02 | D21: 300001047794 | E21: 4120500010 | F21: รายได้-รับเหมาสายใน | G21: CRTD | H21: WACT | I21: 0 | J21: -1158.88 | K21: 1158.88
A22: 320000112670 | B22: 6962 | C22: S/62.69.00096.02 | D22: 320000112670 | E22: 4120500010 | F22: รายได้-รับเหมาสายใน | G22: TECO | H22: ACCO | I22: -3464.68 | J22: -3464.56 | K22: -0.12 | M22: 44439
A23: 300001462822 | B23: 6962 | C23: S/62.69.00125.02 | D23: 300001462822 | E23: 4120500010 | F23: รายได้-รับเหมาสายใน | G23: CRTD | H23: WACT | I23: 0 | J23: -1130.84 | K23: 1130.84
A24: 300001733684 | B24: 6963 | C24: S/63.69.00137.02 | D24: 300001733684 | E24: 4120500010 | F24: รายได้-รับเหมาสายใน | G24: CRTD | H24: WACT | I24: 0 | J24: -11611.22 | K24: 11611.22
A25: 320000118997 | B25: 6962 | C25: S/62.69.00176.02 | D25: 320000118997 | E25: 4120500010 | F25: รายได้-รับเหมาสายใน | G25: TECO | H25: WCLS | I25: -3102.08 | J25: -3102.08 | K25: 0 | M25: 44504
A26: 300001047798 | B26: 6962 | C26: S/62.69.00131.02 | D26: 300001047798 | E26: 4120500010 | F26: รายได้-รับเหมาสายใน | G26: CRTD | H26: WACT | I26: 0 | J26: -1158.88 | K26: 1158.88
A27: 300001047812 | B27: 6962 | C27: S/62.69.00133.02 | D27: 300001047812 | E27: 4120500010 | F27: รายได้-รับเหมาสายใน | G27: CRTD | H27: WACT | I27: 0 | J27: -1158.88 | K27: 1158.88
A28: 300001047800 | B28: 6962 | C28: S/62.69.00134.02 | D28: 300001047800 | E28: 4120500010 | F28: รายได้-รับเหมาสายใน | G28: CRTD | H28: WACT | I28: 0 | J28: -1158.88 | K28: 1158.88
A29: 300001047948 | B29: 6962 | C29: S/62.69.00121.02 | D29: 300001047948 | E29: 4120500010 | F29: รายได้-รับเหมาสายใน | G29: CRTD | H29: WACT | I29: 0 | J29: -1158.88 | K29: 1158.88
A30: 320000112670 | B30: 6962 | C30: S/62.69.00097.02 | D30: 320000112670 | E30: 4120500010 | F30: รายได้-รับเหมาสายใน | G30: TECO | H30: ACCO | I30: -3098.87 | J30: -3098.99 | K30: 0.12 | M30: 44439
A31: 300001663889 | B31: 6962 | C31: S/62.69.00146.02 | D31: 300001663889 | E31: 4120500010 | F31: รายได้-รับเหมาสายใน | G31: CRTD | H31: WACT | I31: 0 | J31: -77383.18 | K31: 77383.18
A32: 300001047801 | B32: 6962 | C32: S/62.69.00130.02 | D32: 300001047801 | E32: 4120500010 | F32: รายได้-รับเหมาสายใน | G32: CRTD | H32: WACT | I32: 0 | J32: -2738.32 | K32: 2738.32
A33: 300001047620 | B33: 6962 | C33: S/62.69.00117.02 | D33: 300001047620 | E33: 4120500010 | F33: รายได้-รับเหมาสายใน | G33: CRTD | H33: WACT | I33: 0 | J33: -1476.64 | K33: 1476.64
A34: 300001047799 | B34: 6962 | C34: S/62.69.00135.02 | D34: 300001047799 | E34: 4120500010 | F34: รายได้-รับเหมาสายใน | G34: CRTD | H34: WACT | I34: 0 | J34: -1158.88 | K34: 1158.88
A35: 300001045008 | B35: 6962 | C35: S/62.69.00127.02 | D35: 300001045008 | E35: 4120500010 | F35: รายได้-รับเหมาสายใน | G35: CRTD | H35: WACT | I35: 0 | J35: -2803.74 | K35: 2803.74
A36: 300001681006 | B36: 6962 | C36: S/62.69.00158.02 | D36: 300001681006 | E36: 4120500010 | F36: รายได้-รับเหมาสายใน | G36: CRTD | H36: WACT | I36: 0 | J36: -48063.6 | K36: 48063.6
A37: 300001045009 | B37: 6962 | C37: S/62.69.00116.02 | D37: 300001045009 | E37: 4120500010 | F37: รายได้-รับเหมาสายใน | G37: CRTD | H37: WACT | I37: 0 | J37: -6850.47 | K37: 6850.47
A38: 320000119715 | B38: 6962 | C38: S/62.69.00205.02 | D38: 320000119715 | E38: 4120500010 | F38: รายได้-รับเหมาสายใน | G38: TECO | H38: ACCO | I38: -9467.29 | J38: -9467.29 | K38: 0 | M38: 44504
A39: 320000121329 | B39: 6963 | C39: S/63.69.00015.02 | D39: 320000121329 | E39: 4120500010 | F39: รายได้-รับเหมาสายใน | G39: TECO | H39: ACCO | I39: -5351.65 | J39: -5328.39 | K39: -23.26 | M39: 44439
A40: 300001704509 | B40: 6962 | C40: S/62.69.00197.02 | D40: 300001704509 | E40: 4120500010 | F40: รายได้-รับเหมาสายใน | G40: CRTD | H40: WACT | I40: 0 | J40: -10650.59 | K40: 10650.59
...

Sheet Sheet2
A1: Row Labels | B1: Sum of ยอดเงินที่บันทึก | C1: *-1 | D1: ZPSR049 | E1: Diff | F1: Status | G1: User Status | H1: TECO Date
A2: S/35.67.00002.01 | B2: 6742.32 | C2: -6742.32 | D2: -6742.32 | E2: 0 | F2: REL | G2: WACT | H2: 0
A3: S/35.67.00003.01 | B3: 1930.58 | C3: -1930.58 | D3: -1930.58 | E3: 0 | F3: REL | G3: WACT | H3: 0
A4: S/58.56.00635.05 | B4: 9579.44 | C4: -9579.44 | D4: -9579.44 | E4: 0 | F4: CLSD | G4: ACCO | H4: 44288
A5: S/60.56.00261.02 | B5: 91951.48 | C5: -91951.48 | D5: -91951.48 | E5: 0 | F5: TECO | G5: ACCO | H5: 44439
A6: S/60.56.00262.02 | B6: 23570.56 | C6: -23570.56 | D6: -23570.56 | E6: 0 | F6: TECO | G6: ACCO | H6: 44439
A7: S/60.56.00263.02 | B7: 37455.76 | C7: -37455.76 | D7: -37455.76 | E7: 0 | F7: TECO | G7: ACCO | H7: 44439
A8: S/60.56.00266.02 | B8: 33201.04 | C8: -33201.04 | D8: -33201.04 | E8: 0 | F8: TECO | G8: ACCO | H8: 44439
A9: S/60.56.00267.02 | B9: 63689.66 | C9: -63689.66 | D9: -63689.66 | E9: 0 | F9: TECO | G9: ACCO | H9: 44439
A10: S/60.56.00268.02 | B10: 21477.3 | C10: -21477.3 | D10: -21477.3 | E10: 0 | F10: TECO | G10: ACCO | H10: 44439
A11: S/60.60.00279.05 | B11: 261.68 | C11: -261.68 | D11: -261.68 | E11: 0 | F11: CRTD | G11: WACT | H11: 0
A12: S/60.66.00338.02 | B12: 18627.04 | C12: -18627.04 | D12: -18627.04 | E12: 0 | F12: CRTD | G12: WACT | H12: 0
A13: S/60.66.00339.02 | B13: 3055.2 | C13: -3055.2 | D13: -3055.2 | E13: 0 | F13: CRTD | G13: WACT | H13: 0
... A122: S/61.56.00347.05 | B122: 12467.29 | C122: -12467.29 | D122: -12467.29 | E122: 0 | F122: CRTD | G122: WACT | H122: 0
A123: S/61.56.00348.05 | B123: 0 | C123: 0 | D123: #N/A | E123: #N/A | F123: #N/A | G123: #N/A | H123: #N/A
A124: S/61.56.00350.02 | B124: 1044.04 | C124: -1044.04 | D124: -1044.04 | E124: 0 | F124: CRTD | G124: WACT | H124: 0
A125: S/61.56.00351.02 | B125: 5656.89 | C125: -5656.89 | D125: -5656.89 | E125: 0 | F125: CRTD | G125: WACT | H125: 0
A126: S/61.56.00361.05 | B126: 1177.57 | C126: -1177.57 | D126: -1177.57 | E126: 0 | F126: CRTD | G126: WACT | H126: 0
A127: S/61.56.00367.05 | B127: 77351.06 | C127: -77351.06 | D127: -77351.06 | E127: 0 | F127: CRTD | G127: WACT | H127: 0
A128: S/61.56.00368.05 | B128: 20162.96 | C128: -20162.96 | D128: -20162.96 | E128: 0 | F128: CRTD | G128: WACT | H128: 0
A129: S/61.56.00369.05 | B129: 78343.62 | C129: -78343.62 | D129: -78343.62 | E129: 0 | F129: CRTD | G129: WACT | H129: 0
A130: S/61.56.00370.05 | B130: 21189.09 | C130: -21189.09 | D130: -21189.09 | E130: 0 | F130: CRTD | G130: WACT | H130: 0
A131: S/61.56.00371.05 | B131: 25059.33 | C131: -25059.33 | D131: -25059.33 | E131: 0 | F131: CRTD | G131: WACT | H131: 0
A132: S/61.56.00372.05 | B132: 7277.12 | C132: -7277.12 | D132: -7277.12 | E132: 0 | F132: CRTD | G132: WACT | H132: 0
A133: S/61.56.00376.05 | B133: 6532.71 | C133: -6532.71 | D133: -6532.71 | E133: 0 | F133: CLSD | G133: ACCO | H133: 44288
A134: S/61.56.00377.05 | B134: 6532.71 | C134: -6532.71 | D134: -6532.71 | E134: 0 | F134: CRTD | G134: WACT | H134: 0
A135: S/61.56.00380.05 | B135: 68962.92 | C135: -68962.92 | D135: -68962.92 | E135: 0 | F135: CRTD | G135: WACT | H135: 0
... A341: S/61.58.00452.02 | B341: 277.07 | C341: -277.07 | D341: -277.07 | E341: 0 | F341: CRTD | G341: WACT | H341: 0
A342: S/61.59.00467.02 | B342: 0 | C342: 0 | D342: #N/A | E342: #N/A | F342: #N/A | G342: #N/A | H342: #N/A
A343: S/61.60.00006.05 | B343: 261.68 | C343: -261.68 | D343: -261.68 | E343: 0 | F343: CRTD | G343: WACT | H343: 0
A344: S/61.60.00007.01 | B344: 5925.23 | C344: -5925.23 | D344: -5925.23 | E344: 0 | F344: CRTD | G344: WACT | H344: 0
A345: S/61.60.00018.01 | B345: 6336.45 | C345: -6336.45 | D345: -6336.45 | E345: 0 | F345: CRTD | G345: WACT | H345: 0
A346: S/61.60.00019.02 | B346: 48317.76 | C346: -48317.76 | D346: -48317.76 | E346: 0 | F346: CRTD | G346: WACT | H346: 0
A347: S/61.60.00028.02 | B347: 8532.71 | C347: -8532.71 | D347: -8532.71 | E347: 0 | F347: CRTD | G347: WACT | H347: 0
A348: S/61.60.00030.02 | B348: 119532.71 | C348: -119532.71 | D348: -119532.71 | E348: 0 | F348: CRTD | G348: WACT | H348: 0
A349: S/61.60.00033.02 | B349: 12664.39 | C349: -12664.39 | D349: -12664.39 | E349: 0 | F349: CRTD | G349: WACT | H349: 0
A350: S/61.60.00048.02 | B350: 6336.45 | C350: -6336.45 | D350: -6336.45 | E350: 0 | F350: CRTD | G350: WACT | H350: 0
A351: S/61.60.00057.05 | B351: 225364.49 | C351: -225364.49 | D351: -225364.49 | E351: 0 | F351: CRTD | G351: WACT | H351: 0
A352: S/61.60.00080.02 | B352: 12797.86 | C352: -12797.86 | D352: -12797.86 | E352: 0 | F352: CRTD | G352: WACT | H352: 0
A353: S/61.60.00092.02 | B353: 62570.09 | C353: -62570.09 | D353: -62570.09 | E353: 0 | F353: CRTD | G353: WACT | H353: 0
...

Sheet Sheet3
A1: Row Labels | B1: noti | C1: Sum of ยอดเงินที่บันทึก | D1: *-1 | E1: ZPSR049 | F1: Diff | G1: Status | H1: User Status | I1: TECO Date
A2: S/62.75.00366.02 | B2: =VLOOKUP(A2,Sheet1!C:D,2,0) -> 300001590128 | C2: 43738.32 | D2: -43738.32 | E2: -161775.7 | F2: 118037.38 | G2: CLSD | H2: ACCO | I2: 44496 | J2: =E2=F2 -> FALSE | K2: แก้เป็น case by case ไป
A3: S/63.29.00022.05 | B3: =VLOOKUP(A3,Sheet1!C:D,2,0) -> 500000004683 | C3: 37872.56 | D3: -37872.56 | E3: -28175.72 | F3: -9696.84 | G3: REL | H3: WACT | I3: 0 | J3: =E3=F3 -> FALSE
A4: S/63.29.00026.05 | B4: =VLOOKUP(A4,Sheet1!C:D,2,0) -> 500000004683 | C4: 21641.46 | D4: -21641.46 | E4: -16100.41 | F4: -5541.05 | G4: CRTD | H4: WACT | I4: 0 | J4: =E4=F4 -> FALSE
A5: S/63.29.00027.05 | B5: =VLOOKUP(A5,Sheet1!C:D,2,0) -> 500000004684 | C5: 243705.97 | D5: -243705.97 | E5: 0 | F5: -243705.97 | G5: CRTD | H5: WACT | I5: 0 | J5: =E5=F5 -> FALSE
A6: S/63.58.00502.02 | B6: =VLOOKUP(A6,Sheet1!C:D,2,0) -> 320000129914 | C6: -327.1 | D6: 327.1 | E6: -327.1 | F6: 654.2 | G6: CLSD | H6: ACCO | I6: 44467 | J6: =E6=F6 -> FALSE
A7: S/63.66.00255.05 | B7: =VLOOKUP(A7,Sheet1!C:D,2,0) -> 320000129202 | C7: 24196.26 | D7: -24196.26 | E7: -12098.13 | F7: -12098.13 | G7: CRTD | H7: WACT | I7: 0 | J7: =E7=F7 -> TRUE
A8: S/63.67.00174.01 | B8: =VLOOKUP(A8,Sheet1!C:D,2,0) -> 320000127580 | C8: 0 | D8: 0 | E8: -7607.48 | F8: 7607.48 | G8: CLSD | H8: ACCO | I8: 44456 | J8: =E8=F8 -> FALSE
A9: S/63.80.00216.02 | B9: =VLOOKUP(A9,Sheet1!C:D,2,0) -> 320000125986 | C9: -12775.7 | D9: 12775.7 | E9: -12775.7 | F9: 25551.4 | G9: CLSD | H9: ACCO | I9: 44348 | J9: =E9=F9 -> FALSE
A10: S/64.56.00137.05 | B10: =VLOOKUP(A10,Sheet1!C:D,2,0) -> 320000136410 | C10: 20082.4 | D10: -20082.4 | E10: -10045.03 | F10: -10037.37 | G10: CLSD | H10: ACCO | I10: 44505 | J10: =E10=F10 -> FALSE
A11: S/64.56.00138.05 | B11: =VLOOKUP(A11,Sheet1!C:D,2,0) -> 320000136410 | C11: 33412.92 | D11: -33412.92 | E11: -16702.63 | F11: -16710.29 | G11: CLSD | H11: ACCO | I11: 44505 | J11: =E11=F11 -> FALSE
A12: S/64.56.00280.05 | B12: =VLOOKUP(A12,Sheet1!C:D,2,0) -> 320000140771 | C12: 115816.82 | D12: -115816.82 | E12: -115828.42 | F12: 11.6 | G12: CLSD | H12: ACCO | I12: 44616 | J12: =E12=F12 -> FALSE
A13: S/64.56.00281.05 | B13: =VLOOKUP(A13,Sheet1!C:D,2,0) -> 320000140771 | C13: 21248.6 | D13: -21248.6 | E13: -21237 | F13: -11.6 | G13: CLSD | H13: ACCO | I13: 44616 | J13: =E13=F13 -> FALSE
A14: S/64.56.00318.05 | B14: =VLOOKUP(A14,Sheet1!C:D,2,0) -> 300001966079 | C14: 391757.01 | D14: -391757.01 | E14: -783514.02 | F14: 391757.01 | G14: REL | H14: WACT | I14: 0 | J14: =E14=F14 -> FALSE
... A51: S/64.80.00403.02 | B51: =VLOOKUP(A51,Sheet1!C:D,2,0) -> 320000141553 | C51: -359.32 | D51: 359.32 | E51: 0 | F51: 359.32 | G51: CLSD | H51: ACCO | I51: 44567 | J51: =E51=F51 -> FALSE

Sheet Sheet4
A1: Row Labels | C1: Sum of ยอดเงินที่บันทึก | D1: Sum of ยอดเงินที่บันทึก*-1 | E1: ZPSR049 | F1: Diff | G1: Status | H1: User Status | I1: TECO Date
A2: S/35.67.00002.01 | B2: 320000150069 | C2: 6742.32 | D2: -6742.32 | E2: -6742.32 | F2: 0 | G2: REL | H2: WACT
A3: S/35.67.00003.01 | B3: 320000150069 | C3: 1930.58 | D3: -1930.58 | E3: -1930.58 | F3: 0 | G3: REL | H3: WACT
A4: S/58.56.00635.05 | B4: 320000063684 | C4: 9579.44 | D4: -9579.44 | E4: -9579.44 | F4: 0 | G4: CLSD | H4: ACCO | I4: 44288
A5: S/60.56.00261.02 | B5: 320000086780 | C5: 91951.48 | D5: -91951.48 | E5: -91951.48 | F5: 0 | G5: TECO | H5: ACCO | I5: 44439
A6: S/60.56.00262.02 | B6: 320000086780 | C6: 23570.56 | D6: -23570.56 | E6: -23570.56 | F6: 0 | G6: TECO | H6: ACCO | I6: 44439
A7: S/60.56.00263.02 | B7: 320000086780 | C7: 37455.76 | D7: -37455.76 | E7: -37455.76 | F7: 0 | G7: TECO | H7: ACCO | I7: 44439
A8: S/60.56.00266.02 | B8: 320000086780 | C8: 33201.04 | D8: -33201.04 | E8: -33201.04 | F8: 0 | G8: TECO | H8: ACCO | I8: 44439
A9: S/60.56.00267.02 | B9: 320000086780 | C9: 63689.66 | D9: -63689.66 | E9: -63689.66 | F9: 0 | G9: TECO | H9: ACCO | I9: 44439
A10: S/60.56.00268.02 | B10: 320000086780 | C10: 21477.3 | D10: -21477.3 | E10: -21477.3 | F10: 0 | G10: TECO | H10: ACCO | I10: 44439
A11: S/60.60.00279.05 | B11: 300001335498 | C11: 261.68 | D11: -261.68 | E11: -261.68 | F11: 0 | G11: CRTD | H11: WACT
A12: S/60.66.00338.02 | B12: 300001356110 | C12: 18627.04 | D12: -18627.04 | E12: -18627.04 | F12: 0 | G12: CRTD | H12: WACT
A13: S/60.66.00339.02 | B13: 300001356110 | C13: 3055.2 | D13: -3055.2 | E13: -3055.2 | F13: 0 | G13: CRTD | H13: WACT
A14: S/60.66.00340.02 | B14: 300001356494 | C14: 24833.38 | D14: -24833.38 | E14: -24833.38 | F14: 0 | G14: CRTD | H14: WACT
A15: S/60.66.00341.02 | B15: 300001356494 | C15: 4073.16 | D15: -4073.16 | E15: -4073.16 | F15: 0 | G15: CRTD | H15: WACT
A16: S/60.66.00342.02 | B16: 300001356111 | C16: 66136.34 | D16: -66136.34 | E16: -66136.34 | F16: 0 | G16: CRTD | H16: WACT
A17: S/60.66.00343.02 | B17: 300001356111 | C17: 3704.78 | D17: -3704.78 | E17: -3704.78 | F17: 0 | G17: CRTD | H17: WACT
A18: S/60.66.00344.02 | B18: 300001356492 | C18: 93103.1 | D18: -93103.1 | E18: -93103.1 | F18: 0 | G18: CRTD | H18: WACT
A19: S/60.66.00345.02 | B19: 300001356492 | C19: 15270.73 | D19: -15270.73 | E19: -15270.73 | F19: 0 | G19: CRTD | H19: WACT
A20: S/60.66.00346.02 | B20: 300001326183 | C20: 1158.88 | D20: -1158.88 | E20: -1158.88 | F20: 0 | G20: CRTD | H20: WACT
A21: S/60.67.00319.05 | B21: 320000090735 | C21: 78850.47 | D21: -78850.47 | E21: -78850.47 | F21: 0 | G21: REL | H21: WACT
A22: S/60.69.00009.02 | B22: 320000069587 | C22: 29510.21 | D22: -29510.21 | E22: -29510.21 | F22: 0 | G22: TECO | H22: ACCO | I22: 44301
A23: S/60.69.00010.02 | B23: 320000069587 | C23: 2361.82 | D23: -2361.82 | E23: -2361.82 | F23: 0 | G23: TECO | H23: ACCO | I23: 44301
A24: S/60.69.00011.02 | B24: 320000069587 | C24: 16099.93 | D24: -16099.93 | E24: -16099.93 | F24: 0 | G24: TECO | H24: ACCO | I24: 44301
A25: S/60.70.00202.02 | B25: 300001250199 | C25: 66859.81 | D25: -66859.81 | E25: -66859.81 | F25: 0 | G25: CLSD | H25: ACCO | I25: 44287
A26: S/60.79.00163.02 | B26: 300001350950 | C26: 89302.95 | D26: -89302.95 | E26: -89302.95 | F26: 0 | G26: CRTD | H26: WACT
A27: S/60.79.00164.02 | B27: 300001350950 | C27: 70397.98 | D27: -70397.98 | E27: -70397.98 | F27: 0 | G27: CRTD | H27: WACT
A28: S/61.29.00012.05 | B28: 500000003821 | C28: 1003037.4 | D28: -1003037.4 | E28: -1003037.4 | F28: 0 | G28: REL | H28: WACT
A29: S/61.29.00013.05 | B29: 500000003830 | C29: 767392.52 | D29: -767392.52 | E29: -767392.52 | F29: 0 | G29: REL | H29: WACT
A30: S/61.29.00014.05 | B30: 500000003751 | C30: 1300214.4 | D30: -1300214.4 | E30: -1300214.4 | F30: 0 | G30: REL | H30: WACT
A31: S/61.29.00015.05 | B31: 500000003751 | C31: 1225916.4 | D31: -1225916.4 | E31: -1225916.4 | F31: 0 | G31: REL | H31: WACT
A32: S/61.29.00016.05 | B32: 500000003901 | C32: 780186.92 | D32: -780186.92 | E32: -780186.92 | F32: 0 | G32: REL | H32: WACT
A33: S/61.29.00017.05 | B33: 500000003946 | C33: 1604831.8 | D33: -1604831.8 | E33: -1604831.8 | F33: 0 | G33: REL | H33: WACT
A34: S/61.29.00018.05 | B34: 500000003752 | C34: 1687617.9 | D34: -1687617.9 | E34: -1687617.9 | F34: 0 | G34: REL | H34: WACT
A35: S/61.29.00019.05 | B35: 500000003752 | C35: 1592092.4 | D35: -1592092.4 | E35: -1592092.4 | F35: 0 | G35: REL | H35: WACT
A36: S/61.29.00020.05 | B36: 500000003894 | C36: 341775.7 | D36: -341775.7 | E36: -341775.7 | F36: 0 | G36: REL | H36: WACT
A37: S/61.29.00021.05 | B37: 500000003902 | C37: 811969.6 | D37: -811969.6 | E37: -811969.6 | F37: 0 | G37: REL | H37: WACT
A38: S/61.29.00022.05 | B38: 500000003902 | C38: 850179.93 | D38: -850179.93 | E38: -850179.93 | F38: 0 | G38: REL | H38: WACT
A39: S/61.29.00023.25 | B39: 500000004061 | C39: 1218486 | D39: -1218486 | E39: -1218486 | F39: 0 | G39: TECO | H39: WCLS | I39: 44613
A40: S/61.29.00026.05 | B40: 500000003903 | C40: 280280.37 | D40: -280280.37 | E40: -280280.37 | F40: 0 | G40: REL | H40: WACT
...

Sheet Sheet5
A1: Row Labels | C1: Sum of ยอดเงินที่บันทึก | D1: Sum of ยอดเงินที่บันทึก*-1 | E1: ZPSR049 | F1: Diff | H1: Diff | I1: Status | J1: User Status | K1: TECO Date
A2: S/63.29.00022.05 | B2: 500000004683 | C2: 37872.56 | D2: -37872.56 | E2: -28175.72 | F2: =E2-D2 -> 9696.84 | G2: =D2=F2 -> FALSE | H2: -9696.84 | I2: REL | J2: WACT | L2: =E2=H2 -> FALSE | M2: ไม่ต้องปรับ บอลมากระจายให้เข้าตัว S64 ไป
A3: S/63.29.00026.05 | B3: 500000004683 | C3: 21641.46 | D3: -21641.46 | E3: -16100.41 | F3: =E3-D3 -> 5541.05 | G3: =D3=F3 -> FALSE | H3: -5541.05 | I3: CRTD | J3: WACT | L3: =E3=H3 -> FALSE | M3: ไม่ต้องปรับ บอลมากระจายให้เข้าตัว S64 ไป
A4: S/63.29.00027.05 | B4: 500000004684 | C4: 243705.97 | D4: -243705.97 | E4: 0 | F4: =E4-D4 -> 243705.97 | G4: =D4=F4 -> FALSE | H4: -243705.97 | I4: CRTD | J4: WACT | L4: =E4=H4 -> FALSE | M4: ไม่ต้องปรับ บอลมากระจายให้เข้าตัว S64 ไป
A5: S/63.66.00255.05 | B5: 320000129202 | C5: 24196.26 | D5: -24196.26 | E5: -12098.13 | F5: =E5-D5 -> 12098.13 | G5: =D5=F5 -> FALSE | H5: -12098.13 | I5: CRTD | J5: WACT | L5: =E5=H5 -> TRUE | M5: ไม่ต้องปรับ บอลมากระจายให้เข้าตัว S64 ไป
A6: S/63.67.00174.01 | B6: 320000127580 | C6: 0 | D6: 0 | E6: -7607.48 | F6: =E6-D6 -> -7607.48 | G6: =D6=F6 -> FALSE | H6: 7607.48 | I6: CLSD | J6: ACCO | K6: 44456 | L6: =E6=H6 -> FALSE | M6: มีคื้นเงิน แต่ยอด CJR2 ไม่รวมคืนเงิน
A7: S/64.56.00137.05 | B7: 320000136410 | C7: 20082.4 | D7: -20082.4 | E7: -10045.03 | F7: =E7-D7 -> 10037.37 | G7: =D7=F7 -> FALSE | H7: -10037.37 | I7: CLSD | J7: ACCO | K7: 44505 | L7: =E7=H7 -> FALSE | M7: CJR2 ถูกแล้ว เพราะ SO ทำ cc ไม่ถูกต้อง
A8: S/64.56.00138.05 | B8: 320000136410 | C8: 33412.92 | D8: -33412.92 | E8: -16702.63 | F8: =E8-D8 -> 16710.29 | G8: =D8=F8 -> FALSE | H8: -16710.29 | I8: CLSD | J8: ACCO | K8: 44505 | L8: =E8=H8 -> FALSE | M8: CJR2 ถูกแล้ว เพราะ SO ทำ cc ไม่ถูกต้อง
A9: S/64.56.00318.05 | B9: 300001966079 | C9: 391757.01 | D9: -391757.01 | E9: -783514.02 | F9: =E9-D9 -> -391757.01 | G9: =D9=F9 -> TRUE | H9: 391757.01 | I9: REL | J9: WACT | L9: =E9=H9 -> FALSE | M9: แก้ Plan dup *2
A10: S/64.56.00322.05 | B10: 300001974854 | C10: 879794.39 | D10: -879794.39 | E10: -1759588.8 | F10: =E10-D10 -> -879794.39 | G10: =D10=F10 -> TRUE | H10: 879794.39 | I10: REL | J10: WACT | L10: =E10=H10 -> FALSE | M10: แก้ Plan dup *2
A11: S/64.57.00262.02 | B11: 300001971350 | C11: 125046.73 | D11: -125046.73 | E11: -375140.19 | F11: =E11-D11 -> -250093.46 | G11: =D11=F11 -> FALSE | H11: 250093.46 | I11: REL | J11: WACT | L11: =E11=H11 -> FALSE | M11: แก้ Plan dup *3
A12: S/64.58.00791.02 | B12: 300001795017 | C12: 3160.99 | D12: -3160.99 | E12: -6308.41 | F12: =E12-D12 -> -3147.42 | G12: =D12=F12 -> FALSE | H12: 3147.42 | I12: CLSD | J12: ACCO | K12: 44617 | L12: =E12=H12 -> FALSE
A13: S/64.58.00792.02 | B13: 300001799621 | C13: 4728.44 | D13: -4728.44 | E13: -9457.94 | F13: =E13-D13 -> -4729.5 | G13: =D13=F13 -> FALSE | H13: 4729.5 | I13: CLSD | J13: ACCO | K13: 44617 | L13: =E13=H13 -> FALSE
A14: S/64.58.00796.02 | B14: 300001848438 | C14: 10002.18 | D14: -10002.18 | E14: -20028.04 | F14: =E14-D14 -> -10025.86 | G14: =D14=F14 -> FALSE | H14: 10025.86 | I14: CLSD | J14: ACCO | K14: 44617 | L14: =E14=H14 -> FALSE
A15: S/64.66.00076.05 | B15: 320000137589 | C15: -464878.5 | D15: 464878.5 | E15: 0 | F15: =E15-D15 -> -464878.5 | G15: =D15=F15 -> FALSE | H15: 464878.5 | I15: CRTD | J15: WACT | L15: =E15=H15 -> FALSE | M15: ไม่แน่ใจทำไมหาย
A16: S/64.66.00096.05 | B16: 320000138283 | C16: 50093.46 | D16: -50093.46 | E16: -25046.73 | F16: =E16-D16 -> 25046.73 | G16: =D16=F16 -> FALSE | H16: -25046.73 | I16: REL | J16: WACT | L16: =E16=H16 -> TRUE | M16: CJR2 ถูกแล้ว เพราะ SO ทำ cc ไม่ถูกต้อง
A17: S/64.66.00145.05 | B17: 320000140848 | C17: 14013.88 | D17: -14013.88 | E17: -42041.64 | F17: =E17-D17 -> -28027.76 | G17: =D17=F17 -> FALSE | H17: 28027.76 | I17: REL | J17: WACT | L17: =E17=H17 -> FALSE | M17: แก้ Plan dup *3
A18: S/64.66.00146.05 | B18: 320000140848 | C18: 182322.57 | D18: -182322.57 | E18: -546967.71 | F18: =E18-D18 -> -364645.14 | G18: =D18=F18 -> FALSE | H18: 364645.14 | I18: REL | J18: WACT | L18: =E18=H18 -> FALSE | M18: แก้ Plan dup *3
A19: S/64.68.00279.05 | B19: 320000125334 | C19: 52703.37 | D19: -52703.37 | E19: -71953.43 | F19: =E19-D19 -> -19250.06 | G19: =D19=F19 -> FALSE | H19: 19250.06 | I19: TECO | J19: WCLS | K19: 44680 | L19: =E19=H19 -> FALSE | M19: ยอด plan รวมไม่ถูกต้อง รอ cf กับบอล
A20: S/64.68.00280.05 | B20: 320000125334 | C20: 32659.6 | D20: -32659.6 | E20: -44588.63 | F20: =E20-D20 -> -11929.03 | G20: =D20=F20 -> FALSE | H20: 11929.03 | I20: TECO | J20: WCLS | K20: 44680 | L20: =E20=H20 -> FALSE | M20: ยอด plan รวมไม่ถูกต้อง รอ cf กับบอล
A21: S/64.69.00098.02 | B21: 300001971171 | C21: 82327.1 | D21: -82327.1 | E21: -246981.3 | F21: =E21-D21 -> -164654.2 | G21: =D21=F21 -> FALSE | H21: 164654.2 | I21: REL | J21: WACT | L21: =E21=H21 -> FALSE | M21: แก้ Plan dup *3
A22: S/64.69.00185.02 | B22: 300001984867 | C22: 1306.2 | D22: -1306.2 | E22: -2612.4 | F22: =E22-D22 -> -1306.2 | G22: =D22=F22 -> TRUE | H22: 1306.2 | I22: TECO | J22: ACCO | K22: 44676 | L22: =E22=H22 -> FALSE | M22: แก้ Plan dup *2
A23: S/64.69.00186.02 | B23: 300001984867 | C23: 675.11 | D23: -675.11 | E23: -1350.22 | F23: =E23-D23 -> -675.11 | G23: =D23=F23 -> TRUE | H23: 675.11 | I23: TECO | J23: ACCO | K23: 44676 | L23: =E23=H23 -> FALSE | M23: แก้ Plan dup *2
A24: S/64.70.00206.02 | B24: 320000136909 | C24: 15140.18 | D24: -15140.18 | E24: -7570.09 | F24: =E24-D24 -> 7570.09 | G24: =D24=F24 -> FALSE | H24: -7570.09 | I24: CLSD | J24: ACCO | K24: 44634 | L24: =E24=H24 -> TRUE | M24: CJR2 ถูกแล้ว เพราะ SO ทำ cc ไม่ถูกต้อง
A25: S/64.70.00325.05 | B25: 300001971758 | C25: 51242.99 | D25: -51242.99 | E25: -102485.98 | F25: =E25-D25 -> -51242.99 | G25: =D25=F25 -> TRUE | H25: 51242.99 | I25: REL | J25: WACT | L25: =E25=H25 -> FALSE | M25: แก้ Plan dup *2
A26: S/64.70.00411.02 | B26: 300001821558 | C26: 65822.43 | D26: -65822.43 | E26: -131644.86 | F26: =E26-D26 -> -65822.43 | G26: =D26=F26 -> TRUE | H26: 65822.43 | I26: REL | J26: WACT | L26: =E26=H26 -> FALSE | M26: แก้ Plan dup *2
A27: S/64.75.00029.02 | B27: 300001740051 | C27: 85588.78 | D27: -85588.78 | E27: -42794.39 | F27: =E27-D27 -> 42794.39 | G27: =D27=F27 -> FALSE | H27: -42794.39 | I27: CLSD | J27: ACCO | K27: 44531 | L27: =E27=H27 -> TRUE
A28: S/64.77.00177.02 | B28: 300001962488 | C28: -23018.69 | D28: 23018.69 | E28: 0 | F28: =E28-D28 -> -23018.69 | G28: =D28=F28 -> FALSE | H28: 23018.69 | I28: CRTD | J28: WACT | L28: =E28=H28 -> FALSE | M28: ไม่แน่ใจทำไมหาย
A29: S/64.80.00401.02 | B29: 320000141553 | C29: -7302.13 | D29: 7302.13 | E29: 0 | F29: =E29-D29 -> -7302.13 | G29: =D29=F29 -> FALSE | H29: 7302.13 | I29: CLSD | J29: ACCO | K29: 44567 | L29: =E29=H29 -> FALSE
A30: S/64.80.00402.02 | B30: 320000141553 | C30: -2815.19 | D30: 2815.19 | E30: 0 | F30: =E30-D30 -> -2815.19 | G30: =D30=F30 -> FALSE | H30: 2815.19 | I30: CLSD | J30: ACCO | K30: 44567 | L30: =E30=H30 -> FALSE
A31: S/64.80.00403.02 | B31: 320000141553 | C31: -359.32 | D31: 359.32 | E31: 0 | F31: =E31-D31 -> -359.32 | G31: =D31=F31 -> FALSE | H31: 359.32 | I31: CLSD | J31: ACCO | K31: 44567 | L31: =E31=H31 -> FALSE
